<?xml version="1.0" encoding="utf-8"?>
<!-- =================================================================================== -->
<!-- |    This document was autogenerated by xacro from my_robot_integration.urdf.xacro | -->
<!-- |    EDITING THIS FILE BY HAND IS NOT RECOMMENDED                                 | -->
<!-- =================================================================================== -->
<!-- Name your robot here -->
<robot name="rat_bot">
  <link name="dummy_link">
  </link>
  <joint name="dummy_joint" type="fixed">
    <parent link="dummy_link"/>
    <child link="chassis"/>
  </joint>
  <link name="chassis">
    <inertial>
      <origin rpy="0 0 0" xyz="0.000215667966675326 3.22622240976468E-07 -0.0508"/>
      <mass value="19.3499528131755"/>
      <inertia ixx="0.325740839915859" ixy="-3.19805521505135E-05" ixz="4.09795776681259E-18" iyy="0.381046698471184" iyz="-2.0186546107189E-18" izz="0.672432362659258"/>
    </inertial>
    <visual>
      <origin rpy="0 0 0" xyz="0 0 0"/>
      <geometry>
        <mesh filename="package://rat_bot/meshes/chassis.STL"/>
      </geometry>
      <material name="">
        <color rgba="0.792156862745098 0.819607843137255 0.933333333333333 1"/>
      </material>
    </visual>
    <collision>
      <origin rpy="0 0 0" xyz="0 0 0"/>
      <geometry>
        <mesh filename="package://rat_bot/meshes/chassis.STL"/>
      </geometry>
    </collision>
  </link>
  <link name="rear_axle">
    <inertial>
      <origin rpy="0 0 0" xyz="0 0.3302 3.54973767868205E-18"/>
      <mass value="5.47892692412034"/>
      <inertia ixx="0.0422116754174596" ixy="1.54158479016256E-19" ixz="-5.33756964679349E-19" iyy="0.0251915820814547" iyz="-3.42745878554697E-20" izz="0.0422116754174596"/>
    </inertial>
    <visual>
      <origin rpy="0 0 0" xyz="0 0 0"/>
      <geometry>
        <mesh filename="package://rat_bot/meshes/rear_axle.STL"/>
      </geometry>
      <material name="">
        <color rgba="0.752941176470588 0.752941176470588 0.752941176470588 1"/>
      </material>
    </visual>
    <collision>
      <origin rpy="0 0 0" xyz="0 0 0"/>
      <geometry>
        <mesh filename="package://rat_bot/meshes/rear_axle.STL"/>
      </geometry>
    </collision>
  </link>
  <joint name="rear_axle_continuous" type="continuous">
    <origin rpy="0 0 0" xyz="-0.14848598412278 -0.330208611508917 -0.0508"/>
    <parent link="chassis"/>
    <child link="rear_axle"/>
    <axis xyz="0 -1 0"/>
  </joint>
  <link name="front_right_axle">
    <inertial>
      <origin rpy="0 0 0" xyz="0.00107004546547312 -0.0805167898427103 -0.060836167708994"/>
      <mass value="0.310636803973422"/>
      <inertia ixx="0.000623132949903208" ixy="5.73940351430201E-06" ixz="3.20864102320735E-20" iyy="0.000191341270284429" iyz="-1.86471644842778E-19" izz="0.000546254978933711"/>
    </inertial>
    <visual>
      <origin rpy="0 0 0" xyz="0 0 0"/>
      <geometry>
        <mesh filename="package://rat_bot/meshes/front_right_axle.STL"/>
      </geometry>
      <material name="">
        <color rgba="0.752941176470588 0.752941176470588 0.752941176470588 1"/>
      </material>
    </visual>
    <collision>
      <origin rpy="0 0 0" xyz="0 0 0"/>
      <geometry>
        <mesh filename="package://rat_bot/meshes/front_right_axle.STL"/>
      </geometry>
    </collision>
  </link>
  <joint name="front_right_axle_revolute" type="revolute">
    <origin rpy="0 0 0" xyz="0.35951 -0.050809 0.0127"/>
    <parent link="chassis"/>
    <child link="front_right_axle"/>
    <axis xyz="0 0 -1"/>
    <limit effort="100" lower="-0.5" upper="0.5" velocity="10"/>
  </joint>
  <link name="front_right_wheel">
    <inertial>
      <origin rpy="0 0 0" xyz="-0.000506293564028357 0.0380966358990794 2.42680039592254E-17"/>
      <mass value="2.36300514046469"/>
      <inertia ixx="0.00739058429423119" ixy="-6.82679268466141E-05" ixz="-2.19875424938179E-19" iyy="0.0125265749461757" iyz="3.23794524781728E-18" izz="0.00738967703270596"/>
    </inertial>
    <visual>
      <origin rpy="0 0 0" xyz="0 0 0"/>
      <geometry>
        <mesh filename="package://rat_bot/meshes/front_right_wheel.STL"/>
      </geometry>
      <material name="">
        <color rgba="0.792156862745098 0.819607843137255 0.933333333333333 1"/>
      </material>
    </visual>
    <collision>
      <origin rpy="0 0 0" xyz="0 0 0"/>
      <geometry>
        <mesh filename="package://rat_bot/meshes/front_right_wheel.STL"/>
      </geometry>
    </collision>
  </link>
  <joint name="front_right_wheel_continuous" type="continuous">
    <origin rpy="0 0 0" xyz="0.00165389230915937 -0.124449010603659 -0.0635000000000001"/>
    <parent link="front_right_axle"/>
    <child link="front_right_wheel"/>
    <axis xyz="0.0132885449876211 -0.99991170338791 0"/>
  </joint>
  <link name="front_left_axle">
    <inertial>
      <origin rpy="0 0 0" xyz="-0.000356993729427948 0.0805231084804262 -0.0608361677089941"/>
      <mass value="0.310636803973422"/>
      <inertia ixx="0.000623200735124786" ixy="1.91495775025319E-06" ixz="3.8890560499949E-20" iyy="0.000191273485062851" iyz="3.27002484028911E-19" izz="0.000546254978933712"/>
    </inertial>
    <visual>
      <origin rpy="0 0 0" xyz="0 0 0"/>
      <geometry>
        <mesh filename="package://rat_bot/meshes/front_left_axle.STL"/>
      </geometry>
      <material name="">
        <color rgba="0.752941176470588 0.752941176470588 0.752941176470588 1"/>
      </material>
    </visual>
    <collision>
      <origin rpy="0 0 0" xyz="0 0 0"/>
      <geometry>
        <mesh filename="package://rat_bot/meshes/front_left_axle.STL"/>
      </geometry>
    </collision>
  </link>
  <joint name="front_left_axle_revolute" type="revolute">
    <origin rpy="0 0 0" xyz="0.35951 0.050791 0.0127"/>
    <parent link="chassis"/>
    <child link="front_left_axle"/>
    <axis xyz="0 0 -1"/>
    <limit effort="100" lower="-0.5" upper="0.5" velocity="10"/>
  </joint>
  <link name="front_left_wheel">
    <inertial>
      <origin rpy="0 0 0" xyz="0.000168912100877855 -0.0380996255716795 3.65928631643131E-17"/>
      <mass value="2.36300514046469"/>
      <inertia ixx="0.00738977801592431" ixy="-2.27776623969502E-05" ixz="-3.18492963814954E-23" iyy="0.0125273812244826" iyz="-4.98526057575346E-18" izz="0.00738967703270596"/>
    </inertial>
    <visual>
      <origin rpy="0 0 0" xyz="0 0 0"/>
      <geometry>
        <mesh filename="package://rat_bot/meshes/front_left_wheel.STL"/>
      </geometry>
      <material name="">
        <color rgba="0.792156862745098 0.819607843137255 0.933333333333333 1"/>
      </material>
    </visual>
    <collision>
      <origin rpy="0 0 0" xyz="0 0 0"/>
      <geometry>
        <mesh filename="package://rat_bot/meshes/front_left_wheel.STL"/>
      </geometry>
    </collision>
  </link>
  <joint name="front_left_wheel_continuous" type="continuous">
    <origin rpy="0 0 0" xyz="-0.000551779529534266 0.124458776867486 -0.0635000000000001"/>
    <parent link="front_left_axle"/>
    <child link="front_left_wheel"/>
    <axis xyz="-0.00443338847448438 0.999990172485027 0"/>
  </joint>
  <transmission name="rear_axle_continuous_trans_block">
    <type>transmission_interface/SimpleTransmission</type>
    <joint name="rear_axle_continuous">
      <hardwareInterface>VelocityJointInterface</hardwareInterface>
    </joint>
    <actuator name="rear_axle_continuous_motor">
      <mechanicalReduction>1</mechanicalReduction>
      <hardwareInterface>VelocityJointInterface</hardwareInterface>
    </actuator>
  </transmission>
  <transmission name="front_right_axle_revolute_trans_block">
    <type>transmission_interface/SimpleTransmission</type>
    <joint name="front_right_axle_revolute">
      <hardwareInterface>EffortJointInterface</hardwareInterface>
    </joint>
    <actuator name="front_right_axle_revolute_motor">
      <mechanicalReduction>1</mechanicalReduction>
      <hardwareInterface>EffortJointInterface</hardwareInterface>
    </actuator>
  </transmission>
  <transmission name="front_left_axle_revolute_trans_block">
    <type>transmission_interface/SimpleTransmission</type>
    <joint name="front_left_axle_revolute">
      <hardwareInterface>EffortJointInterface</hardwareInterface>
    </joint>
    <actuator name="front_left_axle_revolute_motor">
      <mechanicalReduction>1</mechanicalReduction>
      <hardwareInterface>EffortJointInterface</hardwareInterface>
    </actuator>
  </transmission>
  <link name="base_laser">
    <inertial>
      <origin rpy="0 0 0" xyz="-0.00029774 0.0066667 0.00013047"/>
      <mass value="0.15717"/>
      <inertia ixx="6.7885E-05" ixy="-1.3987E-07" ixz="-8.1554E-07" iyy="0.00013173" iyz="-9.0932E-08" izz="7.1972E-05"/>
    </inertial>
    <visual>
      <origin rpy="0 0 0" xyz="0 0 0"/>
      <geometry>
        <mesh filename="/home/madhunc/catkin_ws/src/rat_bot/meshes/ydlidar.dae"/>
      </geometry>
      <material name="">
        <color rgba="0.64706 0.61961 0.58824 1"/>
      </material>
    </visual>
    <collision>
      <origin rpy="0 0 0" xyz="0 0 0"/>
      <geometry>
        <mesh filename="/home/madhunc/catkin_ws/src/rat_bot/meshes/ydlidar.dae"/>
      </geometry>
    </collision>
  </link>
  <link name="laser_frame">
    <inertial>
      <origin rpy="0 0 0" xyz="-0.00036659 0.00064155 -0.00027052"/>
      <mass value="0.25482"/>
      <inertia ixx="8.9194E-05" ixy="1.8116E-07" ixz="3.6435E-08" iyy="0.00018279" iyz="2.423E-07" izz="0.00011103"/>
    </inertial>
    <!--visual>
      <origin
        xyz="0 0 0"
        rpy="0 0 0" />
      <geometry>
        <mesh
          filename="$(find rat_bot)/meshes/ydlidar.dae" />
      </geometry>
      <material
        name="">
        <color
          rgba="0.64706 0.61961 0.58824 1" />
      </material>
    </visual-->
    <!--collision>
      <origin
        xyz="0 0 0"
        rpy="0 0 0" />
      <geometry>
        <mesh
          filename="$(find rat_bot)/meshes/ydlidar.dae" />
      </geometry>
    </collision-->
  </link>
  <joint name="laser_joint" type="fixed">
    <origin rpy="0 0 0" xyz="0 0 0.03172"/>
    <parent link="base_laser"/>
    <child link="laser_frame"/>
    <axis xyz="0 0 0"/>
  </joint>
  <!-- Add your gazebo sensors here -->
  <gazebo reference="base_laser">
    <!-- <gravity>true</gravity> -->
    <!-- Gazebo has fixed set of Sensors types. Check them out here <> -->
    <sensor name="laser" type="ray">
      <!-- Add in your sensor characteristics -->
      <pose> 0 0 0 0 0 0 </pose>
      <visualise>true</visualise>
      <update_rate>40</update_rate>
      <!-- <always_on>true</always_on> -->
      <ray>
        <scan>
          <horizontal>
            <samples>720</samples>
            <resolution>1</resolution>
            <min_angle>-1.570796</min_angle>
            <max_angle>1.570796</max_angle>
          </horizontal>
        </scan>
        <range>
          <min>0.10</min>
          <max>30.0</max>
          <resolution>0.01</resolution>
        </range>
        <noise>
          <type>gaussian</type>
          <mean>0.0</mean>
          <stddev>0.01</stddev>
        </noise>
      </ray>
      <plugin filename="libgazebo_ros_laser.so" name="gazebo_ros_head_hokuyo_controller">
        <!-- Use topic name as /my_robot/scan -->
        <topicName>/rat_bot/scan</topicName>
        <frameName>laser_frame</frameName>
      </plugin>
    </sensor>
  </gazebo>
  <!--  Gazebo plugin for control here is already added for you -->
  <gazebo>
    <plugin filename="libgazebo_ros_control.so" name="gazebo_ros_control">
      <robotNamespace>/rat_bot</robotNamespace>
      <robotSimType>gazebo_ros_control/DefaultRobotHWSim</robotSimType>
      <legacyModeNS>true</legacyModeNS>
    </plugin>
  </gazebo>
  <!-- Create a joint between your robot and sensor -->
  <joint name="lidar_joint" type="fixed">
    <origin rpy="0 0 0" xyz="0 0 0"/>
    <parent link="chassis"/>
    <child link="base_laser"/>
  </joint>
</robot>
