<?xml version="1.0" encoding="utf-8"?>
<!-- This URDF was automatically created by SolidWorks to URDF Exporter! Originally created by Stephen Brawner (brawner@gmail.com) 
     Commit Version: 1.6.0-1-g15f4949  Build Version: 1.6.7594.29634
     For more information, please see http://wiki.ros.org/sw_urdf_exporter -->
<robot
  name="rat_bot">
    <link 
    name="dummy_link">
  </link>
  <joint
    name="dummy_joint"
    type="fixed">
    <parent
      link="dummy_link" />
    <child
      link="chassis" />
  </joint>
  <link
    name="chassis">
    <inertial>
      <origin
        xyz="0.000215667966675326 3.22622240976468E-07 -0.0508"
        rpy="0 0 0" />
      <mass
        value="19.3499528131755" />
      <inertia
        ixx="0.325740839915859"
        ixy="-3.19805521505135E-05"
        ixz="4.09795776681259E-18"
        iyy="0.381046698471184"
        iyz="-2.0186546107189E-18"
        izz="0.672432362659258" />
    </inertial>
    <visual>
      <origin
        xyz="0 0 0"
        rpy="0 0 0" />
      <geometry>
        <mesh
          filename="package://rat_bot/meshes/chassis.STL" />
      </geometry>
      <material
        name="">
        <color
          rgba="0.792156862745098 0.819607843137255 0.933333333333333 1" />
      </material>
    </visual>
    <collision>
      <origin
        xyz="0 0 0"
        rpy="0 0 0" />
      <geometry>
        <mesh
          filename="package://rat_bot/meshes/chassis.STL" />
      </geometry>
    </collision>
  </link>
  <link
    name="rear_axle">
    <inertial>
      <origin
        xyz="0 0.3302 3.54973767868205E-18"
        rpy="0 0 0" />
      <mass
        value="5.47892692412034" />
      <inertia
        ixx="0.0422116754174596"
        ixy="1.54158479016256E-19"
        ixz="-5.33756964679349E-19"
        iyy="0.0251915820814547"
        iyz="-3.42745878554697E-20"
        izz="0.0422116754174596" />
    </inertial>
    <visual>
      <origin
        xyz="0 0 0"
        rpy="0 0 0" />
      <geometry>
        <mesh
          filename="package://rat_bot/meshes/rear_axle.STL" />
      </geometry>
      <material
        name="">
        <color
          rgba="0.752941176470588 0.752941176470588 0.752941176470588 1" />
      </material>
    </visual>
    <collision>
      <origin
        xyz="0 0 0"
        rpy="0 0 0" />
      <geometry>
        <mesh
          filename="package://rat_bot/meshes/rear_axle.STL" />
      </geometry>
    </collision>
  </link>
  <joint
    name="rear_axle_continuous"
    type="continuous">
    <origin
      xyz="-0.14848598412278 -0.330208611508917 -0.0508"
      rpy="0 0 0" />
    <parent
      link="chassis" />
    <child
      link="rear_axle" />
    <axis
      xyz="0 -1 0" />
  </joint>
  <link
    name="front_right_axle">
    <inertial>
      <origin
        xyz="0.00107004546547312 -0.0805167898427103 -0.060836167708994"
        rpy="0 0 0" />
      <mass
        value="0.310636803973422" />
      <inertia
        ixx="0.000623132949903208"
        ixy="5.73940351430201E-06"
        ixz="3.20864102320735E-20"
        iyy="0.000191341270284429"
        iyz="-1.86471644842778E-19"
        izz="0.000546254978933711" />
    </inertial>
    <visual>
      <origin
        xyz="0 0 0"
        rpy="0 0 0" />
      <geometry>
        <mesh
          filename="package://rat_bot/meshes/front_right_axle.STL" />
      </geometry>
      <material
        name="">
        <color
          rgba="0.752941176470588 0.752941176470588 0.752941176470588 1" />
      </material>
    </visual>
    <collision>
      <origin
        xyz="0 0 0"
        rpy="0 0 0" />
      <geometry>
        <mesh
          filename="package://rat_bot/meshes/front_right_axle.STL" />
      </geometry>
    </collision>
  </link>
  <joint
    name="front_right_axle_revolute"
    type="revolute">
    <origin
      xyz="0.35951 -0.050809 0.0127"
      rpy="0 0 0" />
    <parent
      link="chassis" />
    <child
      link="front_right_axle" />
    <axis
      xyz="0 0 -1" />
    <limit
      lower="-0.5"
      upper="0.5"
      effort="100"
      velocity="10" />
  </joint>
  <link
    name="front_right_wheel">
    <inertial>
      <origin
        xyz="-0.000506293564028357 0.0380966358990794 2.42680039592254E-17"
        rpy="0 0 0" />
      <mass
        value="2.36300514046469" />
      <inertia
        ixx="0.00739058429423119"
        ixy="-6.82679268466141E-05"
        ixz="-2.19875424938179E-19"
        iyy="0.0125265749461757"
        iyz="3.23794524781728E-18"
        izz="0.00738967703270596" />
    </inertial>
    <visual>
      <origin
        xyz="0 0 0"
        rpy="0 0 0" />
      <geometry>
        <mesh
          filename="package://rat_bot/meshes/front_right_wheel.STL" />
      </geometry>
      <material
        name="">
        <color
          rgba="0.792156862745098 0.819607843137255 0.933333333333333 1" />
      </material>
    </visual>
    <collision>
      <origin
        xyz="0 0 0"
        rpy="0 0 0" />
      <geometry>
        <mesh
          filename="package://rat_bot/meshes/front_right_wheel.STL" />
      </geometry>
    </collision>
  </link>
  <joint
    name="front_right_wheel_continuous"
    type="continuous">
    <origin
      xyz="0.00165389230915937 -0.124449010603659 -0.0635000000000001"
      rpy="0 0 0" />
    <parent
      link="front_right_axle" />
    <child
      link="front_right_wheel" />
    <axis
      xyz="0.0132885449876211 -0.99991170338791 0" />
  </joint>
  <link
    name="front_left_axle">
    <inertial>
      <origin
        xyz="-0.000356993729427948 0.0805231084804262 -0.0608361677089941"
        rpy="0 0 0" />
      <mass
        value="0.310636803973422" />
      <inertia
        ixx="0.000623200735124786"
        ixy="1.91495775025319E-06"
        ixz="3.8890560499949E-20"
        iyy="0.000191273485062851"
        iyz="3.27002484028911E-19"
        izz="0.000546254978933712" />
    </inertial>
    <visual>
      <origin
        xyz="0 0 0"
        rpy="0 0 0" />
      <geometry>
        <mesh
          filename="package://rat_bot/meshes/front_left_axle.STL" />
      </geometry>
      <material
        name="">
        <color
          rgba="0.752941176470588 0.752941176470588 0.752941176470588 1" />
      </material>
    </visual>
    <collision>
      <origin
        xyz="0 0 0"
        rpy="0 0 0" />
      <geometry>
        <mesh
          filename="package://rat_bot/meshes/front_left_axle.STL" />
      </geometry>
    </collision>
  </link>
  <joint
    name="front_left_axle_revolute"
    type="revolute">
    <origin
      xyz="0.35951 0.050791 0.0127"
      rpy="0 0 0" />
    <parent
      link="chassis" />
    <child
      link="front_left_axle" />
    <axis
      xyz="0 0 -1" />
    <limit
      lower="-0.5"
      upper="0.5"
      effort="100"
      velocity="10" />
  </joint>
  <link
    name="front_left_wheel">
    <inertial>
      <origin
        xyz="0.000168912100877855 -0.0380996255716795 3.65928631643131E-17"
        rpy="0 0 0" />
      <mass
        value="2.36300514046469" />
      <inertia
        ixx="0.00738977801592431"
        ixy="-2.27776623969502E-05"
        ixz="-3.18492963814954E-23"
        iyy="0.0125273812244826"
        iyz="-4.98526057575346E-18"
        izz="0.00738967703270596" />
    </inertial>
    <visual>
      <origin
        xyz="0 0 0"
        rpy="0 0 0" />
      <geometry>
        <mesh
          filename="package://rat_bot/meshes/front_left_wheel.STL" />
      </geometry>
      <material
        name="">
        <color
          rgba="0.792156862745098 0.819607843137255 0.933333333333333 1" />
      </material>
    </visual>
    <collision>
      <origin
        xyz="0 0 0"
        rpy="0 0 0" />
      <geometry>
        <mesh
          filename="package://rat_bot/meshes/front_left_wheel.STL" />
      </geometry>
    </collision>
  </link>
  <joint
    name="front_left_wheel_continuous"
    type="continuous">
    <origin
      xyz="-0.000551779529534266 0.124458776867486 -0.0635000000000001"
      rpy="0 0 0" />
    <parent
      link="front_left_axle" />
    <child
      link="front_left_wheel" />
    <axis
      xyz="-0.00443338847448438 0.999990172485027 0" />
  </joint>
  <transmission name="rear_axle_continuous_trans_block">
    <type>transmission_interface/SimpleTransmission</type>
    <joint name="rear_axle_continuous">
      <hardwareInterface>VelocityJointInterface</hardwareInterface>
    </joint>
    <actuator name="rear_axle_continuous_motor">
      <mechanicalReduction>1</mechanicalReduction>
      <hardwareInterface>VelocityJointInterface</hardwareInterface>
    </actuator>
  </transmission>

  <transmission name="front_right_axle_revolute_trans_block">
    <type>transmission_interface/SimpleTransmission</type>
    <joint name="front_right_axle_revolute">
      <hardwareInterface>EffortJointInterface</hardwareInterface>
    </joint>
    <actuator name="front_right_axle_revolute_motor">
      <mechanicalReduction>1</mechanicalReduction>
      <hardwareInterface>EffortJointInterface</hardwareInterface>
    </actuator>
  </transmission>

  <transmission name="front_left_axle_revolute_trans_block">
    <type>transmission_interface/SimpleTransmission</type>
    <joint name="front_left_axle_revolute">
      <hardwareInterface>EffortJointInterface</hardwareInterface>
    </joint>
    <actuator name="front_left_axle_revolute_motor">
      <mechanicalReduction>1</mechanicalReduction>
      <hardwareInterface>EffortJointInterface</hardwareInterface>
    </actuator>
  </transmission>
</robot>